<mujoco>
  <compiler coordinate="local" meshdir="igus/" angle="degree"/>
  <size njmax="6000" nconmax="6000"/>
  <option gravity="0 0 -9.81" integrator="RK4" timestep="0.002" density="1.2" collision="predefined">
  <!--density= 1.2"-->
  <!--collision="predefined"-->
    <flag gravity="enable" contact="enable" passive="enable"/>
  </option>
  <visual>
    <quality shadowsize="4096"/>
    <!--global offwidth="2048" offheight="1152"/-->
    <!--global offwidth="600" offheight="400"/-->
    <global offwidth="1920" offheight="1080"/>
  </visual>
  <asset>
        <mesh file="RL-50_Rotaryeinheit_abkupfer.stl" scale="0.001 0.001 0.001"/>
        <mesh file="igus_base_move.stl" scale="0.001 0.001 0.001"/>
        <mesh file="igus_move.stl" scale="0.001 0.001 0.001"/>
        <mesh file="schlaeger_anbindung-igus_anbindung_extra-1.stl" scale="0.001 0.001 0.001"/>
        <mesh file="schlaeger_anbindung-Tischtennisschlaeger_Butterfly-1.stl" scale="0.001 0.001 0.001"/>
  </asset>
  <worldbody>
    <light diffuse="1.5 1.5 1.5" pos="0 0 8.0" dir="0 0 -1"/>
    <light directional="true" cutoff="60" exponent="1" diffuse="0.1 0.1 0.1" specular=".1 .1 .1" pos=".1 .2 1.3" dir="-.1 -.2 -1.3"/>
    <geom pos="-0.45 0.3 0" name="frame2" type="plane" size="0.6 0.45 0.01" rgba=".45 .5 .5 0.1" solref="0.03 0.06"/>
    <geom pos="0.45 0.125 -0.5125" name="frame" type="box" size="0.1 0.2 0.51" rgba=".35 .4 .4 1" solref="0.03 0.06"/>
    <geom pos="0.0 1.5 -1.2" name="floor" type="plane" size="2.0 2.0 2.0" rgba=".65 .7 .7 0.2" solref="0.03 0.06"/>
    <body pos="0 0 0" name="dummy_block_activation_1">
      <geom type="box" size=".001 .001 .001" rgba="0.5 0.5 0.5 0"/>
      <joint type="slide" name="dummy_joint_activation_1" range="-10 10" axis="1 0 0" limited="false"/>
    </body>
    <body pos="0 0 0" name="dummy_block_activation_2">
      <geom type="box" size=".001 .001 .001" rgba="0.5 0.5 0.5 0"/>
      <joint type="slide" name="dummy_joint_activation_2" range="-10 10" axis="1 0 0" limited="false"/>
    </body>
    <body pos="0 0 0" name="dummy_block_activation_3">
      <geom type="box" size=".001 .001 .001" rgba="0.5 0.5 0.5 0"/>
      <joint type="slide" name="dummy_joint_activation_3" range="-10 10" axis="1 0 0" limited="false"/>
    </body>
    <body pos="0 0 0" name="dummy_block_activation_4">
      <geom type="box" size=".001 .001 .001" rgba="0.5 0.5 0.5 0"/>
      <joint type="slide" name="dummy_joint_activation_4" range="-10 10" axis="1 0 0" limited="false"/>
    </body>
    <body pos="0 0 0" name="dummy_block_activation_5">
      <geom type="box" size=".001 .001 .001" rgba="0.5 0.5 0.5 0"/>
      <joint type="slide" name="dummy_joint_activation_5" range="-10 10" axis="1 0 0" limited="false"/>
    </body>
    <body pos="0 0 0" name="dummy_block_activation_6">
      <geom type="box" size=".001 .001 .001" rgba="0.5 0.5 0.5 0"/>
      <joint type="slide" name="dummy_joint_activation_6" range="-10 10" axis="1 0 0" limited="false"/>
    </body>
    <body pos="0 0 0" name="dummy_block_activation_7">
      <geom type="box" size=".001 .001 .001" rgba="0.5 0.5 0.5 0"/>
      <joint type="slide" name="dummy_joint_activation_7" range="-10 10" axis="1 0 0" limited="false"/>
    </body>
    <body pos="0 0 0" name="dummy_block_activation_8">
      <geom type="box" size=".001 .001 .001" rgba="0.5 0.5 0.5 0"/>
      <joint type="slide" name="dummy_joint_activation_8" range="-10 10" axis="1 0 0" limited="false"/>
    </body>
    <body pos="0.0 -0.037 0.025" name="muscle_1_moving_end">
      <joint type="slide" name="joint_muscle_1" axis="1 0 0" frictionloss = "1000"/>
      <geom type="sphere" size=".03" rgba="0 1 0.5 0.0"/>
      <site name="muscle_1_moving_end" pos="0.0 0.0 0.0" type="sphere" size=".03 0 0" rgba="0 0 0 0"/>
    </body>
    <body pos="0.0 0.037 0.025" name="muscle_2_moving_end">
      <joint type="slide" name="joint_muscle_2" axis="1 0 0" frictionloss = "1000"/>
      <geom type="sphere" size=".03" rgba="0 1 0.5 0.0"/>
      <site name="muscle_2_moving_end" pos="0.0 0.0 0.0" type="sphere" size=".03 0 0"  rgba="0 0 0 0"/>
    </body>
    <body pos="0.0 0.163 0.086" name="muscle_3_moving_end">
      <joint type="slide" name="joint_muscle_3" axis="1 0 0" frictionloss = "1000"/>
      <geom type="sphere" size=".03" rgba="0 1 0.5 0.0"/>
      <site name="muscle_3_moving_end" pos="0.0 0.0 0.0" type="sphere" size=".03 0 0" rgba="0 0 0 0"/>
    </body>
    <body pos="0.0 0.237 0.086" name="muscle_4_moving_end">
      <joint type="slide" name="joint_muscle_4" axis="1 0 0" frictionloss = "1000"/>
      <geom type="sphere" size=".03" rgba="0 1 0.5 0.0"/>
      <site name="muscle_4_moving_end" pos="0.0 0.0 0.0" type="sphere" size=".03 0 0"  rgba="0 0 0 0"/>
    </body>
    <body pos="0.0 0.363 0.086" name="muscle_5_moving_end">
      <joint type="slide" name="joint_muscle_5" axis="1 0 0" frictionloss = "1000"/>
      <geom type="sphere" size=".03" rgba="0 1 0.5 0.0"/>
      <site name="muscle_5_moving_end" pos="0.0 0.0 0.0" type="sphere" size=".03 0 0" rgba="0 0 0 0"/>
    </body>
    <body pos="0.0 0.437 0.086" name="muscle_6_moving_end">
      <joint type="slide" name="joint_muscle_6" axis="1 0 0" frictionloss = "1000"/>
      <geom type="sphere" size=".03" rgba="0 1 0.5 0.0"/>
      <site name="muscle_6_moving_end" pos="0.0 0.0 0.0" type="sphere" size=".03 0 0"  rgba="0 0 0 0"/>
    </body>
    <body pos="0.0 0.563 0.086" name="muscle_7_moving_end">
      <joint type="slide" name="joint_muscle_7" axis="1 0 0" frictionloss = "2500"/>
      <geom type="sphere" size=".03" rgba="0 1 0.5 0.0"/>
      <site name="muscle_7_moving_end" pos="0.0 0.0 0.0" type="sphere" size=".03 0 0" rgba="0 0 0 0"/>
    </body>
    <body pos="0.0 0.637 0.086" name="muscle_8_moving_end">
      <joint type="slide" name="joint_muscle_8" axis="1 0 0" frictionloss = "2500"/>
      <geom type="sphere" size=".03" rgba="0 1 0.5 0.0"/>
      <site name="muscle_8_moving_end" pos="0.0 0.0 0.0" type="sphere" size=".03 0 0"  rgba="0 0 0 0"/>
    </body>
    <body pos="-1.0 -0.037 0.025" name="muscle_1_fixed_end">
      <geom type="box" size=".03 .04 .03" rgba="0.5 0.5 0.5 0.2"/>
      <site name="muscle_1_fixed_end" pos="0.0 0.0 0.0" type="sphere" size=".03 0 0"  rgba="0 0 0 0"/>
    </body>
    <body pos="-1.0 0.037 0.025" name="muscle_2_fixed_end">
      <geom type="box" size=".03 .04 .03" rgba="0.5 0.5 0.5 0.2"/>
      <site name="muscle_2_fixed_end" pos="0.0 0.0 0.0" type="sphere" size=".03 0 0"  rgba="0 0 0 0"/>
    </body>
    <body pos="-0.68 0.163 0.086" name="muscle_3_fixed_end">
      <geom type="box" size=".03 .04 .03" rgba="0.5 0.5 0.5 0.2"/>
      <site name="muscle_3_fixed_end" pos="0.0 0.0 0.0" type="sphere" size=".03 0 0"  rgba="0 0 0 0"/>
    </body>
    <body pos="-0.68 0.237 0.086" name="muscle_4_fixed_end">
      <geom type="box" size=".03 .04 .03" rgba="0.5 0.5 0.5 0.2"/>
      <site name="muscle_4_fixed_end" pos="0.0 0.0 0.0" type="sphere" size=".03 0 0"  rgba="0 0 0 0"/>
    </body>
    <body pos="-0.68 0.363 0.086" name="muscle_5_fixed_end">
      <geom type="box" size=".03 .04 .03" rgba="0.5 0.5 0.5 0.2"/>
      <site name="muscle_5_fixed_end" pos="0.0 0.0 0.0" type="sphere" size=".03 0 0"  rgba="0 0 0 0"/>
    </body>
    <body pos="-0.68 0.437 0.086" name="muscle_6_fixed_end">
      <geom type="box" size=".03 .04 .03" rgba="0.5 0.5 0.5 0.2"/>
      <site name="muscle_6_fixed_end" pos="0.0 0.0 0.0" type="sphere" size=".03 0 0"  rgba="0 0 0 0"/>
    </body>
    <body pos="-0.68 0.563 0.086" name="muscle_7_fixed_end">
      <geom type="box" size=".03 .04 .03" rgba="0.5 0.5 0.5 0.2"/>
      <site name="muscle_7_fixed_end" pos="0.0 0.0 0.0" type="sphere" size=".03 0 0"  rgba="0 0 0 0"/>
    </body>
    <body pos="-0.68 0.637 0.086" name="muscle_8_fixed_end">
      <geom type="box" size=".03 .04 .03" rgba="0.5 0.5 0.5 0.2"/>
      <site name="muscle_8_fixed_end" pos="0.0 0.0 0.0" type="sphere" size=".03 0 0"  rgba="0 0 0 0"/>
    </body>
    <body>
      <site name="muscle_3_tendon_horizontal_point" pos="0.5 0.163 0.086" type="sphere" size=".03 0 0" rgba="0 0 0 0"/>
      <site name="muscle_4_tendon_horizontal_point" pos="0.5 0.237 0.086" type="sphere" size=".03 0 0" rgba="0 0 0 0"/>
      <site name="muscle_5_tendon_horizontal_point" pos="0.5 0.363 0.086" type="sphere" size=".03 0 0" rgba="0 0 0 0"/>
      <site name="muscle_6_tendon_horizontal_point" pos="0.5 0.437 0.086" type="sphere" size=".03 0 0" rgba="0 0 0 0"/>
      <site name="muscle_7_tendon_horizontal_point" pos="0.5 0.563 0.086" type="sphere" size=".03 0 0" rgba="0 0 0 0"/>
      <site name="muscle_8_tendon_horizontal_point" pos="0.5 0.637 0.086" type="sphere" size=".03 0 0" rgba="0 0 0 0"/>
    </body>
    <body pos="0.4350 0.1175 -0.0025" name="arm">
      <site name="tendon_1_base_rot_point_of_contact" pos="0.0 -0.0371 0.01" type="sphere" size=".02 0 0" rgba="1 1 1 0"/>
      <site name="tendon_2_base_rot_point_of_contact" pos="0.0 0.0371 0.01" type="sphere" size=".02 0 0" rgba="1 1 1 0"/>
      <body>
        <joint type="hinge" name="joint_base_rotation" axis="0 0 1"  frictionloss="114.0189"  solreffriction="0.5" solimpfriction="0.75294" limited="true" range="-89.8 89.8" solreflimit="0.003" solimplimit="1"/>
        <geom name="dummy_cylinder_for_tendon_wrapping_1" type = "cylinder" size="0.037 0.01" pos = "0 0 0.01" rgba="1 0 0 0" mass="0.000001"/>
        <geom type = "mesh" mesh="RL-50_Rotaryeinheit_abkupfer" rgba = "0.20 0.20 0.20 1" zaxis="-1 0 0" pos = "0.037 -0.037 0" mass="0.03"/>
        <geom type = "mesh" mesh="RL-50_Rotaryeinheit_abkupfer" rgba = "0.20 0.20 0.20 1" xyaxes="0 0 1 0 -1 0" pos = "-0.0375 0.0375 0.0" mass="0.03"/>
        <site name="tendon_1_base_rot_connection" pos="0.0 -0.0371 0.01" type="sphere" size=".01 0 0" rgba="1 0 0 0"/>
        <site name="tendon_2_base_rot_connection" pos="0.0 0.0371 0.01" type="sphere" size=".01 0 0" rgba="0 1 0 0"/>
        <site name="tendon_1_2_side_opposite_to_muscle" pos="0.0371 0.0 0.01"  type="sphere" size=".01 0 0" rgba="1 0 0 0" />
        <site name="tendon_3_base_rot_point_of_contact" pos="-0.0371 0 0.075" type="sphere" size=".02 0 0" rgba="1 1 1 0"/>
        <site name="tendon_4_base_rot_point_of_contact" pos="0.0371 0 0.075" type="sphere" size=".02 0 0" rgba="1 1 1 0"/>
        <body>
          <geom name="dummy_cylinder_for_tendon_wrapping_2" type = "cylinder" size="0.037 0.01" pos = "0 0.0 0.075" zaxis="0 1 0" rgba="1 0 0 0" mass="0.000001"/>
          <joint type="hinge" name="dof2" axis="0 1 0" pos="0 0 0.075"  frictionloss="111.0899" solreffriction="0.075396" solimpfriction="0.65317" limited="true" range="-89.8 89.8" solreflimit="0.003" solimplimit="1"/>
          <geom type = "mesh" mesh="igus_move" rgba = "0.20 0.20 0.20 1.0" zaxis="0 0 -1" pos = "-0.04 0.0366 0.14" mass="0.03"/>
          <geom type = "cylinder" size="0.013 0.145" pos="0 0 0.235" zaxis="0 0 1" rgba="0.95 0.95 0.95 1.0" mass="0.14822"/>
          <geom type = "mesh" mesh="igus_base_move" rgba = "0.20 0.20 0.20 1.0" pos="-0.036 -0.0325 0.51" zaxis="0 1 0" mass="0.03"/>
          <site name="center_joint_1_2" pos="0 0 0.075" type="sphere" size=".04 0 0" rgba="1 0 1 0"/>
          <site name="tendon_3_base_rot_connection" pos="-0.0371 0 0.075" type="sphere" size=".01 0 0" rgba="1 0 0 0"/>
          <site name="tendon_4_base_rot_connection" pos="0.0371 0 0.075" type="sphere" size=".01 0 0" rgba="0 1 0 0"/>
          <site name="tendon_3_4_side_opposite_to_muscle" pos="0 0 0.1121"  type="sphere" size=".01 0 0" rgba="1 0 0 0" />
          <site name="tendon_5_base_rot_point_of_contact" pos="-0.0371 0 0.425" type="sphere" size=".02 0 0" rgba="1 1 1 0"/>
          <site name="tendon_6_base_rot_point_of_contact" pos="0.0371 0 0.425" type="sphere" size=".02 0 0" rgba="1 1 1 0"/>
          <body  pos="0 0 0.055">
              <geom name="dummy_cylinder_for_tendon_wrapping_3" type = "cylinder" size="0.037 0.01" pos = "0 0 0.425" zaxis="0 1 0" rgba="1 0 0 0" mass="0.000001"/>
              <joint type="hinge" name="dof3" axis="0 1 0" pos="0 0 0.425"  frictionloss="7.7682"  solreffriction="0.5" solimpfriction="0.65914" limited="true" range="-89.8 89.8" solreflimit="0.003" solimplimit="1"/>
              <geom type = "mesh" mesh="igus_move" rgba = "0.20 0.20 0.20 1.0" zaxis="0 0 -1" pos = "-0.04 0.0366 0.49" mass="0.03"/>
              <site name="tendon_5_base_rot_connection" pos="-0.0371 0 0.425" type="sphere" size=".01 0 0" rgba="1 0 0 0"/>
              <site name="tendon_6_base_rot_connection" pos="0.0371 0 0.425" type="sphere" size=".01 0 0" rgba="0 1 0 0"/>
              <site name="tendon_5_6_side_opposite_to_muscle" pos="0.0 0.0 0.4621"  type="sphere" size=".01 0 0" rgba="1 0 0 0" />
              <site name="tendon_7_base_rot_point_of_contact" pos="0 -0.0371 0.425" type="sphere" size=".02 0 0" rgba="1 1 1 0"/>
              <site name="tendon_8_base_rot_point_of_contact" pos="0 0.0371 0.425" type="sphere" size=".02 0 0" rgba="1 1 1 0"/>
              <body>
                  <geom name="dummy_cylinder_for_tendon_wrapping_4" type = "cylinder" size="0.037 0.01" pos = "0 0 0.425" rgba="1 0 0 0" mass="0.000001"/>
                  <joint type="hinge" name="dof4" axis="0 0 1" pos="0 0 0"  frictionloss="111.9529"  solreffriction="0.38711" solimpfriction="2.5699"  limited="true" range="-89.8 89.8" solreflimit="0.003" solimplimit="1"/>
                  <geom type = "cylinder" size="0.013 0.075" pos="0 0 0.555" zaxis="0 0 1" rgba="0.95 0.95 0.95 1.0" mass="0.11402"/>
                  <geom name="racket_handle" type = "mesh" mesh="schlaeger_anbindung-igus_anbindung_extra-1" rgba="0.99 0.99 0.99 1" zaxis = "0 -1 0" pos ="-0.075 0.016 0.615"  mass="0.02"/>
                  <geom name="racket" type = "mesh" mesh="schlaeger_anbindung-Tischtennisschlaeger_Butterfly-1" rgba="0.7 0.05 0.05 1" pos="-0.075 0.016 0.615" zaxis = "0 -1 0" mass="0.66342"/>
                  <!--geoom name="racket" type = "cylinder" size="0.5 0.275" rgba="0.7 0.05 0.05 1" zaxis = "0 -1 0" pos="-0.075 0.016 0.615"  mass="0.02"/-->
                  <site name="center_joint_3_4" pos="0 0 0.425" type="sphere" size=".04 0 0" rgba="1 0 1 0"/>
                  <site name="tendon_7_base_rot_connection" pos="0 -0.0371 0.425" type="sphere" size=".01 0 0" rgba="1 0 0 0"/>
                  <site name="tendon_8_base_rot_connection" pos="0 0.0371 0.425" type="sphere" size=".01 0 0" rgba="0 1 0 0"/>
                  <site name="tendon_7_8_side_opposite_to_muscle" pos="0.0371 0.0 0.425"  type="sphere" size=".01 0 0" rgba="1 0 0 0" />
              </body>
          </body>
        </body>
      </body>
    </body>
    <body pos="0.0 0.0 0.0" name="ball1">
      <geom name="ball1" type="sphere" size=".02" rgba="1.0 0.65 0.1 1" pos="0 0 0" mass="0.0027"/>
      <joint type="free" name="ball_free_jnt"/>
    </body>
    <body pos = "0.8 1.7 -0.475" name = "table">
      <geom name="plate" type="box" size="0.7625 1.37 0.02" rgba="0.05 0.3 0.23 1.0"  zaxis="0 0 1"/>
      <!--geoom name="plate_top" type="plane" pos="0.0 0.0 0.025" size="0.7625 1.5 0.02" rgba="1.0 0.45 0.38 0.5"  zaxis="0 0 1"/>
      <geoom name="plate_bottom" type="plane" pos="0.0 0.0 -0.025" size="0.7625 1.5 0.02" rgba="0.2 0.45 1.0 0.5"  zaxis="0 0 -1"/-->
      <geom name="leg1" pos = "-0.7425 -1.35 -0.38" type="box" size="0.02 0.02 0.38" rgba="0.1 0.1 0.1 1.0"/>
      <geom name="leg2" pos = "0.7425 -1.35 -0.38" type="box" size="0.02 0.02 0.38" rgba="0.1 0.1 0.1 1.0"/>
      <geom name="leg3" pos = "-0.7425 1.35 -0.38" type="box" size="0.02 0.02 0.38" rgba="0.1 0.1 0.1 1.0"/>
      <geom name="leg4" pos = "0.7425 1.35 -0.38" type="box" size="0.02 0.02 0.38" rgba="0.1 0.1 0.1 1.0"/>
      <geom name="net" pos = "0.0 0.0 0.07625" type="box" size="0.7825 0.02 0.07625" rgba="0.1 0.1 0.1 0.4"/>
    </body>
    <body pos = "0.0375 1.7 -0.475" name="goal">
      <geom name="goal_circle_center" type="cylinder" pos="0 0 1" size="0.05 0.0005" rgba="0.2 1.0 0.2 1.0"/>
      <geom name="goal_circle_outer" type="cylinder" pos="0 0 1" size="0.2 0.0004" rgba="0.2 1.0 0.2 0.05"/>
    </body>
    <body pos = "0 0 -0.455" name="hitting_point">
      <geom type="cylinder" size="0.03 0.0007" rgba="1.0 0.65 0.1 1"/>
      <joint type="slide" axis="1 0 0" name="hitting_point_slide_jnt_1"/>
      <joint type="slide" axis="0 1 0" name="hitting_point_slide_jnt_2"/>
    </body>
    <!--body pos = "0.0 0.0 0.0" name="vis_orientation">
      <geom name="center" type="box" pos="0 0 0" size="0.005 0.005 0.005" rgba="0.5 0.5 0.5 1.0"/>
      <geom name="x" type="box" pos="0 0 0" size="0.1 0.003 0.003" rgba="1.0 0.0 0.0 1.0" euler="90 0 0"/>
      <geom name="y" type="box" pos="0 0 0" size="0.1 0.003 0.003" rgba="0.0 1.0 0.0 1.0" euler="0 90 0"/>
      <geom name="z" type="box" pos="0 0 0" size="0.1 0.003 0.003" rgba="0.0 0.0 1.0 1.0" euler="0 0 90"/>
    </body-->
  </worldbody>
  <contact>
    <pair geom1="ball1" geom2="racket" solref="-0.1 -0.1"/>
    <pair geom1="ball1" geom2="floor" solref="0.003 0.25" gap="0.0"/>
    <pair geom1="ball1" geom2="racket_handle" solref="0.003 0.35"/>
    <pair geom1="ball1" geom2="plate" solref="-0.1 -0.1" gap="0.02"/>
    <pair geom1="ball1" geom2="net" solref="0.003 10.0"/>
    <pair geom1="floor" geom2="racket" solref="0.003 0.9"/>
  </contact>
  <tendon>
    <spatial name = "tendon_1" width="0.001" rgba="0.7 0.4 0.4 1.0" limited="true" range="0.0 0.89335" damping="418.6191" solreflimit="0.005" solimplimit="1" stiffness="218205.4346">
      <site site="muscle_1_moving_end"/>
      <site site="tendon_1_base_rot_point_of_contact"/>
      <geom geom="dummy_cylinder_for_tendon_wrapping_1"/>
      <site site="tendon_1_2_side_opposite_to_muscle"/>
      <geom geom="dummy_cylinder_for_tendon_wrapping_1"/>
      <site site="tendon_2_base_rot_connection"/>
    </spatial>
    <spatial name = "tendon_2" width="0.001" rgba="0.7 0.4 0.4 1.0" limited="true" range="0.0 0.89335" damping="418.6191" solreflimit="0.005" solimplimit="1" stiffness="218205.4346">
      <site site="muscle_2_moving_end"/>
      <site site="tendon_2_base_rot_point_of_contact"/>
      <geom geom="dummy_cylinder_for_tendon_wrapping_1"/>
      <site site="tendon_1_2_side_opposite_to_muscle"/>
      <geom geom="dummy_cylinder_for_tendon_wrapping_1"/>
      <site site="tendon_1_base_rot_connection"/>
    </spatial>
    <spatial name = "tendon_3" width="0.001" rgba="0.7 0.4 0.4 0.2" limited="true" range="0.0 0.88194" damping="418.6191" solreflimit="0.005" solimplimit="1" stiffness="218205.4346">
      <site site="muscle_3_moving_end"/>
      <site site="muscle_3_tendon_horizontal_point"/>
      <site site="center_joint_1_2"/>
      <site site="tendon_3_base_rot_point_of_contact"/>
      <geom geom="dummy_cylinder_for_tendon_wrapping_2"/>
      <site site="tendon_3_4_side_opposite_to_muscle"/>
      <geom geom="dummy_cylinder_for_tendon_wrapping_2"/>
      <site site="tendon_4_base_rot_connection"/>
    </spatial>
    <spatial name = "tendon_4" width="0.001" rgba="0.7 0.4 0.4 0.2" limited="true" range="0.0 0.95594" damping="418.6191" solreflimit="0.005" solimplimit="1" stiffness="218205.4346">
      <site site="muscle_4_moving_end"/>
      <site site="muscle_4_tendon_horizontal_point"/>
      <site site="center_joint_1_2"/>
      <site site="tendon_4_base_rot_point_of_contact"/>
      <geom geom="dummy_cylinder_for_tendon_wrapping_2"/>
      <site site="tendon_3_4_side_opposite_to_muscle"/>
      <geom geom="dummy_cylinder_for_tendon_wrapping_2"/>
      <site site="tendon_3_base_rot_connection"/>
    </spatial>
    <spatial name = "tendon_5" width="0.001" rgba="0.7 0.4 0.4 0.2" limited="true" range="0.0 1.293" damping="418.6191" solreflimit="0.005" solimplimit="1" stiffness="218205.4346">
      <site site="muscle_5_moving_end"/>
      <site site="muscle_5_tendon_horizontal_point"/>
      <site site="center_joint_1_2"/>
      <site site="center_joint_3_4"/>
      <site site="tendon_5_base_rot_point_of_contact"/>
      <geom geom="dummy_cylinder_for_tendon_wrapping_3"/>
      <site site="tendon_5_6_side_opposite_to_muscle"/>
      <geom geom="dummy_cylinder_for_tendon_wrapping_3"/>
      <site site="tendon_6_base_rot_connection"/>
    </spatial>
    <spatial name = "tendon_6" width="0.001" rgba="0.7 0.4 0.4 0.2" limited="true" range="0.0 1.367" damping="418.6191" solreflimit="0.005" solimplimit="1" stiffness="218205.4346">
      <site site="muscle_6_moving_end"/>
      <site site="muscle_6_tendon_horizontal_point"/>
      <site site="center_joint_1_2"/>
      <site site="center_joint_3_4"/>
      <site site="tendon_6_base_rot_point_of_contact"/>
      <geom geom="dummy_cylinder_for_tendon_wrapping_3"/>
      <site site="tendon_5_6_side_opposite_to_muscle"/>
      <geom geom="dummy_cylinder_for_tendon_wrapping_3"/>
      <site site="tendon_5_base_rot_connection"/>
    </spatial>
        <spatial name = "tendon_7" width="0.001" rgba="0.7 0.4 0.4 0.2" limited="true" range="0.0 1.3016" damping="418.6191" solreflimit="0.005" solimplimit="1" stiffness="218205.4346">
      <site site="muscle_7_moving_end"/>
      <site site="muscle_7_tendon_horizontal_point"/>
      <site site="center_joint_1_2"/>
      <site site="center_joint_3_4"/>
      <site site="tendon_7_base_rot_point_of_contact"/>
      <geom geom="dummy_cylinder_for_tendon_wrapping_4"/>
      <site site="tendon_7_8_side_opposite_to_muscle"/>
      <geom geom="dummy_cylinder_for_tendon_wrapping_4"/>
      <site site="tendon_8_base_rot_connection"/>
    </spatial>
    <spatial name = "tendon_8" width="0.001" rgba="0.7 0.4 0.4 0.2" limited="true" range="0.0 1.3756" damping="418.6191" solreflimit="0.005" solimplimit="1" stiffness="218205.4346">
      <site site="muscle_8_moving_end"/>
      <site site="muscle_8_tendon_horizontal_point"/>
      <site site="center_joint_1_2"/>
      <site site="center_joint_3_4"/>
      <site site="tendon_8_base_rot_point_of_contact"/>
      <geom geom="dummy_cylinder_for_tendon_wrapping_4"/>
      <site site="tendon_7_8_side_opposite_to_muscle"/>
      <geom geom="dummy_cylinder_for_tendon_wrapping_4"/>
      <site site="tendon_7_base_rot_connection"/>
    </spatial>
    <spatial name = "dummy_tendon_viz_muscle_1" width="0.0125" rgba="0.20 0.20 0.20 1" limited="false" stiffness="0.0">
      <site site="muscle_1_moving_end"/>
      <site site="muscle_1_fixed_end"/>
    </spatial>
    <spatial name = "dummy_tendon_viz_muscle_2" width="0.0125" rgba="0.20 0.20 0.20 1" limited="false" stiffness="0.0">
      <site site="muscle_2_moving_end"/>
      <site site="muscle_2_fixed_end"/>
    </spatial>
    <spatial name = "dummy_tendon_viz_muscle_3" width="0.0125" rgba="0.20 0.20 0.20 0.3" limited="false" stiffness="0.0">
      <site site="muscle_3_moving_end"/>
      <site site="muscle_3_fixed_end"/>
    </spatial>
    <spatial name = "dummy_tendon_viz_muscle_4" width="0.0125" rgba="0.20 0.20 0.20 0.3" limited="false" stiffness="0.0">
      <site site="muscle_4_moving_end"/>
      <site site="muscle_4_fixed_end"/>
    </spatial>
    <spatial name = "dummy_tendon_viz_muscle_5" width="0.0125" rgba="0.20 0.20 0.20 0.3" limited="false" stiffness="0.0">
      <site site="muscle_5_moving_end"/>
      <site site="muscle_5_fixed_end"/>
    </spatial>
    <spatial name = "dummy_tendon_viz_muscle_6" width="0.0125" rgba="0.20 0.20 0.20 0.3" limited="false" stiffness="0.0">
      <site site="muscle_6_moving_end"/>
      <site site="muscle_6_fixed_end"/>
    </spatial>
    <spatial name = "dummy_tendon_viz_muscle_7" width="0.0125" rgba="0.20 0.20 0.20 0.3" limited="false" stiffness="0.0">
      <site site="muscle_7_moving_end"/>
      <site site="muscle_7_fixed_end"/>
    </spatial>
    <spatial name = "dummy_tendon_viz_muscle_8" width="0.0125" rgba="0.20 0.20 0.20 0.3" limited="false" stiffness="0.0">
      <site site="muscle_8_moving_end"/>
      <site site="muscle_8_fixed_end"/>
    </spatial>
  </tendon>
  <actuator>
    <general name = "activation_1" joint="dummy_joint_activation_1" ctrllimited="true" ctrlrange="0.001 1.0" dyntype="filter" dynprm="0.015908 0 0" gaintype="fixed"  gainprm="0 0 0" biastype="none"/>
    <general name = "activation_2" joint="dummy_joint_activation_2" ctrllimited="true" ctrlrange="0.001 1.0" dyntype="filter" dynprm="0.015908 0 0" gaintype="fixed"  gainprm="0 0 0" biastype="none"/>
    <general name = "activation_3" joint="dummy_joint_activation_3" ctrllimited="true" ctrlrange="0.001 1.0" dyntype="filter" dynprm="0.043861 0 0" gaintype="fixed"  gainprm="0 0 0" biastype="none"/>
    <general name = "activation_4" joint="dummy_joint_activation_4" ctrllimited="true" ctrlrange="0.001 1.0" dyntype="filter" dynprm="0.043861 0 0" gaintype="fixed"  gainprm="0 0 0" biastype="none"/>
    <general name = "activation_5" joint="dummy_joint_activation_5" ctrllimited="true" ctrlrange="0.001 1.0" dyntype="filter" dynprm="0.043861 0 0" gaintype="fixed"  gainprm="0 0 0" biastype="none"/>
    <general name = "activation_6" joint="dummy_joint_activation_6" ctrllimited="true" ctrlrange="0.001 1.0" dyntype="filter" dynprm="0.043861 0 0" gaintype="fixed"  gainprm="0 0 0" biastype="none"/>
    <general name = "activation_7" joint="dummy_joint_activation_7" ctrllimited="true" ctrlrange="0.001 1.0" dyntype="filter" dynprm="0.043861 0 0" gaintype="fixed"  gainprm="0 0 0" biastype="none"/>
    <general name = "activation_8" joint="dummy_joint_activation_8" ctrllimited="true" ctrlrange="0.001 1.0" dyntype="filter" dynprm="0.043861 0 0" gaintype="fixed"  gainprm="0 0 0" biastype="none"/>
    <general name = "muscle_1" joint="joint_muscle_1" ctrllimited="false" dyntype="integrator" gaintype="fixed" gainprm="0 0 0" biastype="user"/>
    <general name = "muscle_2" joint="joint_muscle_2" ctrllimited="false" dyntype="integrator" gaintype="fixed" gainprm="0 0 0" biastype="user"/>
    <general name = "muscle_3" joint="joint_muscle_3" ctrllimited="false" dyntype="integrator" gaintype="fixed" gainprm="0 0 0" biastype="user"/>
    <general name = "muscle_4" joint="joint_muscle_4" ctrllimited="false" dyntype="integrator" gaintype="fixed" gainprm="0 0 0" biastype="user"/>
    <general name = "muscle_5" joint="joint_muscle_5" ctrllimited="false" dyntype="integrator" gaintype="fixed" gainprm="0 0 0" biastype="user"/>
    <general name = "muscle_6" joint="joint_muscle_6" ctrllimited="false" dyntype="integrator" gaintype="fixed" gainprm="0 0 0" biastype="user"/>
    <general name = "muscle_7" joint="joint_muscle_7" ctrllimited="false" dyntype="integrator" gaintype="fixed" gainprm="0 0 0" biastype="user"/>
    <general name = "muscle_8" joint="joint_muscle_8" ctrllimited="false" dyntype="integrator" gaintype="fixed" gainprm="0 0 0" biastype="user"/>
  </actuator>
</mujoco>
