<mujoco>
  <compiler coordinate="local" meshdir="igus/" angle="degree"/>
  <size njmax="6000" nconmax="6000"/>
  <option gravity="0 0 -9.81" integrator="RK4" timestep="0.002"  density="1.2" collision="predefined"> <!--collision="predefined"-->
    <flag gravity="enable" contact="enable" passive="enable"/>
  </option>
  <visual>
    <quality shadowsize="4096"/>
    <!--global offwidth="2048" offheight="1152"/-->
    <!--global offwidth="600" offheight="400"/-->
    <global offwidth="1920" offheight="1080"/>
  </visual>
  <asset>
        <mesh file="RL-50_Rotaryeinheit_abkupfer.stl" scale="0.001 0.001 0.001"/>
        <mesh file="igus_base_move.stl" scale="0.001 0.001 0.001"/>
        <mesh file="igus_move.stl" scale="0.001 0.001 0.001"/>
        <mesh file="schlaeger_anbindung-igus_anbindung_extra-1.stl" scale="0.001 0.001 0.001"/>
        <mesh file="schlaeger_anbindung-Tischtennisschlaeger_Butterfly-1.stl" scale="0.001 0.001 0.001"/>
  </asset>
  <worldbody>
    <light diffuse="1.5 1.5 1.5" pos="0 0 8.0" dir="0 0 -1"/>
    <light directional="true" cutoff="60" exponent="1" diffuse="0.1 0.1 0.1" specular=".1 .1 .1" pos=".1 .2 1.3" dir="-.1 -.2 -1.3"/>
    <geom pos="0.0 1.75 -1.2" name="floor" type="plane" size="3.0 3.0 1.0" rgba=".16 .15 0.20 0.9" solref="0.03 0.06"/>


    <body name="robot1" pos="0.0 0.0 -0.5">    
        <include file="robot_1.xml"/>
    </body>

    <body name="robot2" pos="1.6 3.4 -0.5" xyaxes="-1 0 0 0 -1 0">
      <include file="robot_2.xml"/>
    </body>

    <body pos="0.0 0.0 0.0" name="ball1"> 
      <geom name="ball1" type="sphere" size=".02" rgba="1.0 0.65 0.1 1" pos="0 0 0" mass="0.0027"/>
      <joint type="free" name="ball_free_jnt"/>
    </body>
    <body pos = "0.8 1.7 -0.44" name = "table">
      <geom name="plate" type="box" size="0.7625 1.37 0.02" rgba="0.2 0.45 0.38 1.0"  zaxis="0 0 1"/>
      <!--geoom name="plate_top" type="plane" pos="0.0 0.0 0.025" size="0.7625 1.5 0.02" rgba="1.0 0.45 0.38 0.5"  zaxis="0 0 1"/>
      <geoom name="plate_bottom" type="plane" pos="0.0 0.0 -0.025" size="0.7625 1.5 0.02" rgba="0.2 0.45 1.0 0.5"  zaxis="0 0 -1"/-->
      <geom name="leg1" pos = "-0.7425 -1.35 -0.38" type="box" size="0.02 0.02 0.38" rgba="0.1 0.1 0.1 1.0"/>
      <geom name="leg2" pos = "0.7425 -1.35 -0.38" type="box" size="0.02 0.02 0.38" rgba="0.1 0.1 0.1 1.0"/>
      <geom name="leg3" pos = "-0.7425 1.35 -0.38" type="box" size="0.02 0.02 0.38" rgba="0.1 0.1 0.1 1.0"/>
      <geom name="leg4" pos = "0.7425 1.35 -0.38" type="box" size="0.02 0.02 0.38" rgba="0.1 0.1 0.1 1.0"/>
      <geom name="net" pos = "0.0 0.0 0.07625" type="box" size="0.7825 0.02 0.07625" rgba="0.1 0.1 0.1 0.4"/>
    </body>
    <body pos = "0.0375 1.7 -0.44" name="goal">
      <geom name="goal_circle_center" type="cylinder" pos="0 0 1" size="0.05 0.0005" rgba="0.2 1.0 0.2 1.0"/>
      <geom name="goal_circle_outer" type="cylinder" pos="0 0 1" size="0.2 0.0004" rgba="0.2 1.0 0.2 0.1"/>
    </body>
    <body pos = "0.0 0.0 -0.42" name="hitting_point">
      <geom type="cylinder" size="0.03 0.0007" rgba="1.0 0.65 0.1 1"/>
      <joint type="slide" axis="1 0 0" name="hitting_point_slide_jnt_1"/>
      <joint type="slide" axis="0 1 0" name="hitting_point_slide_jnt_2"/>
    </body>
    <!--body pos = "0.0 0.0 0.0" name="vis_orientation">
      <geom name="center" type="box" pos="0 0 0" size="0.005 0.005 0.005" rgba="0.5 0.5 0.5 1.0"/>
      <geom name="x" type="box" pos="0 0 0" size="0.1 0.003 0.003" rgba="1.0 0.0 0.0 1.0" euler="90 0 0"/>
      <geom name="y" type="box" pos="0 0 0" size="0.1 0.003 0.003" rgba="0.0 1.0 0.0 1.0" euler="0 90 0"/>
      <geom name="z" type="box" pos="0 0 0" size="0.1 0.003 0.003" rgba="0.0 0.0 1.0 1.0" euler="0 0 90"/>
    </body-->
  </worldbody>
  <contact>
    <pair geom1="ball1" geom2="1_racket" solref="-0.1 -0.1"/>
    <pair geom1="ball1" geom2="2_racket" solref="-0.1 -0.1"/>
    <pair geom1="ball1" geom2="floor" solref="0.003 0.25" gap="0.0"/>
    <pair geom1="ball1" geom2="1_racket_handle" solref="0.003 0.35"/>
    <pair geom1="ball1" geom2="2_racket_handle" solref="0.003 0.35"/>
    <pair geom1="ball1" geom2="plate" solref="-0.1 -0.1" gap="0.02"/>
    <pair geom1="ball1" geom2="net" solref="0.003 10.0"/>
    <pair geom1="floor" geom2="1_racket" solref="0.003 0.9"/>
    <pair geom1="floor" geom2="2_racket" solref="0.003 0.9"/>
  </contact>
  <include file="actuation.xml"/>
</mujoco>
